Workbook

Sheet Dashboard
B1: ASM PRECONSTRUCTION PIPELINE TRACKER V9 — DASHBOARD
B2: ="All States Mechanical | Data as of: "&TEXT(TODAY(),"mmmm d, yyyy") -> All States Mechanical | Data as of: May 13, 2026
B3: TOTAL BID VOLUME YTD | D3: AWARDED VOLUME YTD | F3: LOST VOLUME YTD | H3: PENDING VOLUME | J3: WIN RATE (BY $)
B4: =IFERROR(SUMIF('Bid Log'!Q:Q,"<>No Bid",'Bid Log'!P:P),0) -> 240963687 | D4: =IFERROR(SUMIF('Bid Log'!Q:Q,"Awarded",'Bid Log'!R:R),0) -> 5240366 | F4: =IFERROR(SUMIF('Bid Log'!Q:Q,"Lost",'Bid Log'!P:P),0) -> 39672921 | H4: =IFERROR(SUMIF('Bid Log'!Q:Q,"Bid Submitted",'Bid Log'!P:P)+SUMIF('Bid Log'!Q:Q,"Budget Submitted",'Bid Log'!P:P)+SUMIF('Bid Log'!Q:Q,"ROM Submitted",'Bid Log'!P:P),0) -> 188708577 | J4: =IFERROR(SUMIF('Bid Log'!Q:Q,"Awarded",'Bid Log'!P:P)/(SUMIF('Bid Log'!Q:Q,"Awarded",'Bid Log'!P:P)+SUMIF('Bid Log'!Q:Q,"Lost",'Bid Log'!P:P)),0) -> 0.14209524
B6: HIGH-PROB PENDING (≥70%) | D6: BIDS DUE NEXT 7 DAYS | F6: FOLLOW-UPS PAST DUE | H6: EXPECTED AWARDS THIS MONTH | J6: WIN RATE (BY COUNT)
B7: =IFERROR(SUMPRODUCT((('Bid Log'!Q:Q="Bid Submitted")+('Bid Log'!Q:Q="Budget Submitted")>0)*('Bid Log'!W:W>=0.7)*'Bid Log'!P:P),0) -> 0 | D7: =IFERROR(COUNTIFS('Bid Log'!L:L,">="&TODAY(),'Bid Log'!L:L,"<="&TODAY()+7,'Bid Log'!Q:Q,"In Progress"),0) -> 0 | F7: =IFERROR(COUNTIF('Bid Log'!AE:AE,"OVERDUE"),0) -> 0 | H7: =IFERROR(COUNTIFS('Bid Log'!V:V,">="&DATE(YEAR(TODAY()),MONTH(TODAY()),1),'Bid Log'!V:V,"<="&EOMONTH(TODAY(),0),'Bid Log'!Q:Q,"Bid Submitted"),0) -> 0 | J7: =IFERROR(COUNTIF('Bid Log'!Q:Q,"Awarded")/(COUNTIF('Bid Log'!Q:Q,"Awarded")+COUNTIF('Bid Log'!Q:Q,"Lost")),0) -> 0.1875
B9: BID VOLUME BY MARKET SEGMENT
B10: Market Segment | E10: # Bids | F10: Bid Volume | H10: # Awarded | I10: # Lost | J10: Awarded $ | L10: Win Rate
B11: Correctional | E11: =COUNTIFS('Bid Log'!E:E,"Correctional",'Bid Log'!Q:Q,"<>No Bid") -> 0 | F11: =IFERROR(SUMIFS('Bid Log'!P:P,'Bid Log'!E:E,"Correctional",'Bid Log'!Q:Q,"<>No Bid"),0) -> 0 | H11: =COUNTIFS('Bid Log'!E:E,"Correctional",'Bid Log'!Q:Q,"Awarded") -> 0 | I11: =COUNTIFS('Bid Log'!E:E,"Correctional",'Bid Log'!Q:Q,"Lost") -> 0 | J11: =IFERROR(SUMIFS('Bid Log'!R:R,'Bid Log'!E:E,"Correctional",'Bid Log'!Q:Q,"Awarded"),0) -> 0 | L11: =IFERROR(H11/(H11+I11),"")
B12: Education | E12: =COUNTIFS('Bid Log'!E:E,"Education",'Bid Log'!Q:Q,"<>No Bid") -> 6 | F12: =IFERROR(SUMIFS('Bid Log'!P:P,'Bid Log'!E:E,"Education",'Bid Log'!Q:Q,"<>No Bid"),0) -> 17443544 | H12: =COUNTIFS('Bid Log'!E:E,"Education",'Bid Log'!Q:Q,"Awarded") -> 0 | I12: =COUNTIFS('Bid Log'!E:E,"Education",'Bid Log'!Q:Q,"Lost") -> 0 | J12: =IFERROR(SUMIFS('Bid Log'!R:R,'Bid Log'!E:E,"Education",'Bid Log'!Q:Q,"Awarded"),0) -> 0 | L12: =IFERROR(H12/(H12+I12),"")
B13: Federal / Government | E13: =COUNTIFS('Bid Log'!E:E,"Federal / Government",'Bid Log'!Q:Q,"<>No Bid") -> 0 | F13: =IFERROR(SUMIFS('Bid Log'!P:P,'Bid Log'!E:E,"Federal / Government",'Bid Log'!Q:Q,"<>No Bid"),0) -> 0 | H13: =COUNTIFS('Bid Log'!E:E,"Federal / Government",'Bid Log'!Q:Q,"Awarded") -> 0 | I13: =COUNTIFS('Bid Log'!E:E,"Federal / Government",'Bid Log'!Q:Q,"Lost") -> 0 | J13: =IFERROR(SUMIFS('Bid Log'!R:R,'Bid Log'!E:E,"Federal / Government",'Bid Log'!Q:Q,"Awarded"),0) -> 0 | L13: =IFERROR(H13/(H13+I13),"")
B14: Food Service | E14: =COUNTIFS('Bid Log'!E:E,"Food Service",'Bid Log'!Q:Q,"<>No Bid") -> 0 | F14: =IFERROR(SUMIFS('Bid Log'!P:P,'Bid Log'!E:E,"Food Service",'Bid Log'!Q:Q,"<>No Bid"),0) -> 0 | H14: =COUNTIFS('Bid Log'!E:E,"Food Service",'Bid Log'!Q:Q,"Awarded") -> 0 | I14: =COUNTIFS('Bid Log'!E:E,"Food Service",'Bid Log'!Q:Q,"Lost") -> 0 | J14: =IFERROR(SUMIFS('Bid Log'!R:R,'Bid Log'!E:E,"Food Service",'Bid Log'!Q:Q,"Awarded"),0) -> 0 | L14: =IFERROR(H14/(H14+I14),"")
B15: Healthcare | E15: =COUNTIFS('Bid Log'!E:E,"Healthcare",'Bid Log'!Q:Q,"<>No Bid") -> 4 | F15: =IFERROR(SUMIFS('Bid Log'!P:P,'Bid Log'!E:E,"Healthcare",'Bid Log'!Q:Q,"<>No Bid"),0) -> 11702023 | H15: =COUNTIFS('Bid Log'!E:E,"Healthcare",'Bid Log'!Q:Q,"Awarded") -> 0 | I15: =COUNTIFS('Bid Log'!E:E,"Healthcare",'Bid Log'!Q:Q,"Lost") -> 1 | J15: =IFERROR(SUMIFS('Bid Log'!R:R,'Bid Log'!E:E,"Healthcare",'Bid Log'!Q:Q,"Awarded"),0) -> 0 | L15: =IFERROR(H15/(H15+I15),"") -> 0
B16: Hotel / Resort | E16: =COUNTIFS('Bid Log'!E:E,"Hotel / Resort",'Bid Log'!Q:Q,"<>No Bid") -> 3 | F16: =IFERROR(SUMIFS('Bid Log'!P:P,'Bid Log'!E:E,"Hotel / Resort",'Bid Log'!Q:Q,"<>No Bid"),0) -> 2343079 | H16: =COUNTIFS('Bid Log'!E:E,"Hotel / Resort",'Bid Log'!Q:Q,"Awarded") -> 0 | I16: =COUNTIFS('Bid Log'!E:E,"Hotel / Resort",'Bid Log'!Q:Q,"Lost") -> 1 | J16: =IFERROR(SUMIFS('Bid Log'!R:R,'Bid Log'!E:E,"Hotel / Resort",'Bid Log'!Q:Q,"Awarded"),0) -> 0 | L16: =IFERROR(H16/(H16+I16),"") -> 0
B17: Industrial / Manufacturing | E17: =COUNTIFS('Bid Log'!E:E,"Industrial / Manufacturing",'Bid Log'!Q:Q,"<>No Bid") -> 1 | F17: =IFERROR(SUMIFS('Bid Log'!P:P,'Bid Log'!E:E,"Industrial / Manufacturing",'Bid Log'!Q:Q,"<>No Bid"),0) -> 1950000 | H17: =COUNTIFS('Bid Log'!E:E,"Industrial / Manufacturing",'Bid Log'!Q:Q,"Awarded") -> 0 | I17: =COUNTIFS('Bid Log'!E:E,"Industrial / Manufacturing",'Bid Log'!Q:Q,"Lost") -> 0 | J17: =IFERROR(SUMIFS('Bid Log'!R:R,'Bid Log'!E:E,"Industrial / Manufacturing",'Bid Log'!Q:Q,"Awarded"),0) -> 0 | L17: =IFERROR(H17/(H17+I17),"")
B18: Mission Critical | E18: =COUNTIFS('Bid Log'!E:E,"Mission Critical",'Bid Log'!Q:Q,"<>No Bid") -> 1 | F18: =IFERROR(SUMIFS('Bid Log'!P:P,'Bid Log'!E:E,"Mission Critical",'Bid Log'!Q:Q,"<>No Bid"),0) -> 12985469 | H18: =COUNTIFS('Bid Log'!E:E,"Mission Critical",'Bid Log'!Q:Q,"Awarded") -> 0 | I18: =COUNTIFS('Bid Log'!E:E,"Mission Critical",'Bid Log'!Q:Q,"Lost") -> 0 | J18: =IFERROR(SUMIFS('Bid Log'!R:R,'Bid Log'!E:E,"Mission Critical",'Bid Log'!Q:Q,"Awarded"),0) -> 0 | L18: =IFERROR(H18/(H18+I18),"")
B19: Multi-Family | E19: =COUNTIFS('Bid Log'!E:E,"Multi-Family",'Bid Log'!Q:Q,"<>No Bid") -> 35 | F19: =IFERROR(SUMIFS('Bid Log'!P:P,'Bid Log'!E:E,"Multi-Family",'Bid Log'!Q:Q,"<>No Bid"),0) -> 175877999 | H19: =COUNTIFS('Bid Log'!E:E,"Multi-Family",'Bid Log'!Q:Q,"Awarded") -> 3 | I19: =COUNTIFS('Bid Log'!E:E,"Multi-Family",'Bid Log'!Q:Q,"Lost") -> 7 | J19: =IFERROR(SUMIFS('Bid Log'!R:R,'Bid Log'!E:E,"Multi-Family",'Bid Log'!Q:Q,"Awarded"),0) -> 5240366 | L19: =IFERROR(H19/(H19+I19),"") -> 0.3
B20: Municipal | E20: =COUNTIFS('Bid Log'!E:E,"Municipal",'Bid Log'!Q:Q,"<>No Bid") -> 3 | F20: =IFERROR(SUMIFS('Bid Log'!P:P,'Bid Log'!E:E,"Municipal",'Bid Log'!Q:Q,"<>No Bid"),0) -> 657224 | H20: =COUNTIFS('Bid Log'!E:E,"Municipal",'Bid Log'!Q:Q,"Awarded") -> 0 | I20: =COUNTIFS('Bid Log'!E:E,"Municipal",'Bid Log'!Q:Q,"Lost") -> 0 | J20: =IFERROR(SUMIFS('Bid Log'!R:R,'Bid Log'!E:E,"Municipal",'Bid Log'!Q:Q,"Awarded"),0) -> 0 | L20: =IFERROR(H20/(H20+I20),"")
B21: Professional Office | E21: =COUNTIFS('Bid Log'!E:E,"Professional Office",'Bid Log'!Q:Q,"<>No Bid") -> 20 | F21: =IFERROR(SUMIFS('Bid Log'!P:P,'Bid Log'!E:E,"Professional Office",'Bid Log'!Q:Q,"<>No Bid"),0) -> 18004349 | H21: =COUNTIFS('Bid Log'!E:E,"Professional Office",'Bid Log'!Q:Q,"Awarded") -> 0 | I21: =COUNTIFS('Bid Log'!E:E,"Professional Office",'Bid Log'!Q:Q,"Lost") -> 4 | J21: =IFERROR(SUMIFS('Bid Log'!R:R,'Bid Log'!E:E,"Professional Office",'Bid Log'!Q:Q,"Awarded"),0) -> 0 | L21: =IFERROR(H21/(H21+I21),"") -> 0
B22: Religious / Cultural | E22: =COUNTIFS('Bid Log'!E:E,"Religious / Cultural",'Bid Log'!Q:Q,"<>No Bid") -> 0 | F22: =IFERROR(SUMIFS('Bid Log'!P:P,'Bid Log'!E:E,"Religious / Cultural",'Bid Log'!Q:Q,"<>No Bid"),0) -> 0 | H22: =COUNTIFS('Bid Log'!E:E,"Religious / Cultural",'Bid Log'!Q:Q,"Awarded") -> 0 | I22: =COUNTIFS('Bid Log'!E:E,"Religious / Cultural",'Bid Log'!Q:Q,"Lost") -> 0 | J22: =IFERROR(SUMIFS('Bid Log'!R:R,'Bid Log'!E:E,"Religious / Cultural",'Bid Log'!Q:Q,"Awarded"),0) -> 0 | L22: =IFERROR(H22/(H22+I22),"")
B23: Retail | E23: =COUNTIFS('Bid Log'!E:E,"Retail",'Bid Log'!Q:Q,"<>No Bid") -> 0 | F23: =IFERROR(SUMIFS('Bid Log'!P:P,'Bid Log'!E:E,"Retail",'Bid Log'!Q:Q,"<>No Bid"),0) -> 0 | H23: =COUNTIFS('Bid Log'!E:E,"Retail",'Bid Log'!Q:Q,"Awarded") -> 0 | I23: =COUNTIFS('Bid Log'!E:E,"Retail",'Bid Log'!Q:Q,"Lost") -> 0 | J23: =IFERROR(SUMIFS('Bid Log'!R:R,'Bid Log'!E:E,"Retail",'Bid Log'!Q:Q,"Awarded"),0) -> 0 | L23: =IFERROR(H23/(H23+I23),"")
B24: Transportation | E24: =COUNTIFS('Bid Log'!E:E,"Transportation",'Bid Log'!Q:Q,"<>No Bid") -> 0 | F24: =IFERROR(SUMIFS('Bid Log'!P:P,'Bid Log'!E:E,"Transportation",'Bid Log'!Q:Q,"<>No Bid"),0) -> 0 | H24: =COUNTIFS('Bid Log'!E:E,"Transportation",'Bid Log'!Q:Q,"Awarded") -> 0 | I24: =COUNTIFS('Bid Log'!E:E,"Transportation",'Bid Log'!Q:Q,"Lost") -> 0 | J24: =IFERROR(SUMIFS('Bid Log'!R:R,'Bid Log'!E:E,"Transportation",'Bid Log'!Q:Q,"Awarded"),0) -> 0 | L24: =IFERROR(H24/(H24+I24),"")
B25: Warehouse / Distribution | E25: =COUNTIFS('Bid Log'!E:E,"Warehouse / Distribution",'Bid Log'!Q:Q,"<>No Bid") -> 0 | F25: =IFERROR(SUMIFS('Bid Log'!P:P,'Bid Log'!E:E,"Warehouse / Distribution",'Bid Log'!Q:Q,"<>No Bid"),0) -> 0 | H25: =COUNTIFS('Bid Log'!E:E,"Warehouse / Distribution",'Bid Log'!Q:Q,"Awarded") -> 0 | I25: =COUNTIFS('Bid Log'!E:E,"Warehouse / Distribution",'Bid Log'!Q:Q,"Lost") -> 0 | J25: =IFERROR(SUMIFS('Bid Log'!R:R,'Bid Log'!E:E,"Warehouse / Distribution",'Bid Log'!Q:Q,"Awarded"),0) -> 0 | L25: =IFERROR(H25/(H25+I25),"")
B27: PLUMB ESTIMATOR WORKLOAD & PERFORMANCE
B28: Plumb Estimator | D28: Active Bids | E28: Active Volume | G28: Awarded | H28: Awarded $ | J28: Lost | K28: Win Rate
B29: Patrick | D29: =COUNTIFS('Bid Log'!I:I,"Patrick",'Bid Log'!Q:Q,"Bid Submitted")+COUNTIFS('Bid Log'!I:I,"Patrick",'Bid Log'!Q:Q,"Budget Submitted")+COUNTIFS('Bid Log'!I:I,"Patrick",'Bid Log'!Q:Q,"In Progress") -> 35 | E29: =IFERROR(SUMIFS('Bid Log'!P:P,'Bid Log'!I:I,"Patrick",'Bid Log'!Q:Q,"Bid Submitted")+SUMIFS('Bid Log'!P:P,'Bid Log'!I:I,"Patrick",'Bid Log'!Q:Q,"Budget Submitted")+SUMIFS('Bid Log'!P:P,'Bid Log'!I:I,"Patrick",'Bid Log'!Q:Q,"In Progress"),0) -> 94086665 | G29: =COUNTIFS('Bid Log'!I:I,"Patrick",'Bid Log'!Q:Q,"Awarded") -> 0 | H29: =IFERROR(SUMIFS('Bid Log'!R:R,'Bid Log'!I:I,"Patrick",'Bid Log'!Q:Q,"Awarded"),0) -> 0 | J29: =COUNTIFS('Bid Log'!I:I,"Patrick",'Bid Log'!Q:Q,"Lost") -> 3 | K29: =IFERROR(G29/(G29+J29),"") -> 0
B30: Cristhian | D30: =COUNTIFS('Bid Log'!I:I,"Cristhian",'Bid Log'!Q:Q,"Bid Submitted")+COUNTIFS('Bid Log'!I:I,"Cristhian",'Bid Log'!Q:Q,"Budget Submitted")+COUNTIFS('Bid Log'!I:I,"Cristhian",'Bid Log'!Q:Q,"In Progress") -> 16 | E30: =IFERROR(SUMIFS('Bid Log'!P:P,'Bid Log'!I:I,"Cristhian",'Bid Log'!Q:Q,"Bid Submitted")+SUMIFS('Bid Log'!P:P,'Bid Log'!I:I,"Cristhian",'Bid Log'!Q:Q,"Budget Submitted")+SUMIFS('Bid Log'!P:P,'Bid Log'!I:I,"Cristhian",'Bid Log'!Q:Q,"In Progress"),0) -> 70533245 | G30: =COUNTIFS('Bid Log'!I:I,"Cristhian",'Bid Log'!Q:Q,"Awarded") -> 3 | H30: =IFERROR(SUMIFS('Bid Log'!R:R,'Bid Log'!I:I,"Cristhian",'Bid Log'!Q:Q,"Awarded"),0) -> 5240366 | J30: =COUNTIFS('Bid Log'!I:I,"Cristhian",'Bid Log'!Q:Q,"Lost") -> 7 | K30: =IFERROR(G30/(G30+J30),"") -> 0.3
B31: Les | D31: =COUNTIFS('Bid Log'!I:I,"Les",'Bid Log'!Q:Q,"Bid Submitted")+COUNTIFS('Bid Log'!I:I,"Les",'Bid Log'!Q:Q,"Budget Submitted")+COUNTIFS('Bid Log'!I:I,"Les",'Bid Log'!Q:Q,"In Progress") -> 4 | E31: =IFERROR(SUMIFS('Bid Log'!P:P,'Bid Log'!I:I,"Les",'Bid Log'!Q:Q,"Bid Submitted")+SUMIFS('Bid Log'!P:P,'Bid Log'!I:I,"Les",'Bid Log'!Q:Q,"Budget Submitted")+SUMIFS('Bid Log'!P:P,'Bid Log'!I:I,"Les",'Bid Log'!Q:Q,"In Progress"),0) -> 16252808 | G31: =COUNTIFS('Bid Log'!I:I,"Les",'Bid Log'!Q:Q,"Awarded") -> 0 | H31: =IFERROR(SUMIFS('Bid Log'!R:R,'Bid Log'!I:I,"Les",'Bid Log'!Q:Q,"Awarded"),0) -> 0 | J31: =COUNTIFS('Bid Log'!I:I,"Les",'Bid Log'!Q:Q,"Lost") -> 2 | K31: =IFERROR(G31/(G31+J31),"") -> 0
B32: Sam | D32: =COUNTIFS('Bid Log'!I:I,"Sam",'Bid Log'!Q:Q,"Bid Submitted")+COUNTIFS('Bid Log'!I:I,"Sam",'Bid Log'!Q:Q,"Budget Submitted")+COUNTIFS('Bid Log'!I:I,"Sam",'Bid Log'!Q:Q,"In Progress") -> 2 | E32: =IFERROR(SUMIFS('Bid Log'!P:P,'Bid Log'!I:I,"Sam",'Bid Log'!Q:Q,"Bid Submitted")+SUMIFS('Bid Log'!P:P,'Bid Log'!I:I,"Sam",'Bid Log'!Q:Q,"Budget Submitted")+SUMIFS('Bid Log'!P:P,'Bid Log'!I:I,"Sam",'Bid Log'!Q:Q,"In Progress"),0) -> 13847000 | G32: =COUNTIFS('Bid Log'!I:I,"Sam",'Bid Log'!Q:Q,"Awarded") -> 0 | H32: =IFERROR(SUMIFS('Bid Log'!R:R,'Bid Log'!I:I,"Sam",'Bid Log'!Q:Q,"Awarded"),0) -> 0 | J32: =COUNTIFS('Bid Log'!I:I,"Sam",'Bid Log'!Q:Q,"Lost") -> 0 | K32: =IFERROR(G32/(G32+J32),"")
B33: No Bid | D33: =COUNTIFS('Bid Log'!I:I,"No Bid",'Bid Log'!Q:Q,"Bid Submitted")+COUNTIFS('Bid Log'!I:I,"No Bid",'Bid Log'!Q:Q,"Budget Submitted")+COUNTIFS('Bid Log'!I:I,"No Bid",'Bid Log'!Q:Q,"In Progress") -> 0 | E33: =IFERROR(SUMIFS('Bid Log'!P:P,'Bid Log'!I:I,"No Bid",'Bid Log'!Q:Q,"Bid Submitted")+SUMIFS('Bid Log'!P:P,'Bid Log'!I:I,"No Bid",'Bid Log'!Q:Q,"Budget Submitted")+SUMIFS('Bid Log'!P:P,'Bid Log'!I:I,"No Bid",'Bid Log'!Q:Q,"In Progress"),0) -> 0 | G33: =COUNTIFS('Bid Log'!I:I,"No Bid",'Bid Log'!Q:Q,"Awarded") -> 0 | H33: =IFERROR(SUMIFS('Bid Log'!R:R,'Bid Log'!I:I,"No Bid",'Bid Log'!Q:Q,"Awarded"),0) -> 0 | J33: =COUNTIFS('Bid Log'!I:I,"No Bid",'Bid Log'!Q:Q,"Lost") -> 0 | K33: =IFERROR(G33/(G33+J33),"")
B35: LOSSES BY REASON
B36: Lost Reason | F36: # Lost | H36: Lost Volume
B37: Price | F37: =COUNTIFS('Bid Log'!U:U,"Price",'Bid Log'!Q:Q,"Lost") -> 3 | H37: =IFERROR(SUMIFS('Bid Log'!P:P,'Bid Log'!U:U,"Price",'Bid Log'!Q:Q,"Lost"),0) -> 20916179
B38: Relationship | F38: =COUNTIFS('Bid Log'!U:U,"Relationship",'Bid Log'!Q:Q,"Lost") -> 1 | H38: =IFERROR(SUMIFS('Bid Log'!P:P,'Bid Log'!U:U,"Relationship",'Bid Log'!Q:Q,"Lost"),0) -> 1084708
B39: Scope Gap | F39: =COUNTIFS('Bid Log'!U:U,"Scope Gap",'Bid Log'!Q:Q,"Lost") -> 0 | H39: =IFERROR(SUMIFS('Bid Log'!P:P,'Bid Log'!U:U,"Scope Gap",'Bid Log'!Q:Q,"Lost"),0) -> 0
B40: Schedule Conflict | F40: =COUNTIFS('Bid Log'!U:U,"Schedule Conflict",'Bid Log'!Q:Q,"Lost") -> 0 | H40: =IFERROR(SUMIFS('Bid Log'!P:P,'Bid Log'!U:U,"Schedule Conflict",'Bid Log'!Q:Q,"Lost"),0) -> 0
B41: No Award | F41: =COUNTIFS('Bid Log'!U:U,"No Award",'Bid Log'!Q:Q,"Lost") -> 0 | H41: =IFERROR(SUMIFS('Bid Log'!P:P,'Bid Log'!U:U,"No Award",'Bid Log'!Q:Q,"Lost"),0) -> 0
B42: Withdrawn by Owner | F42: =COUNTIFS('Bid Log'!U:U,"Withdrawn by Owner",'Bid Log'!Q:Q,"Lost") -> 0 | H42: =IFERROR(SUMIFS('Bid Log'!P:P,'Bid Log'!U:U,"Withdrawn by Owner",'Bid Log'!Q:Q,"Lost"),0) -> 0
B43: Competition Too Strong | F43: =COUNTIFS('Bid Log'!U:U,"Competition Too Strong",'Bid Log'!Q:Q,"Lost") -> 0 | H43: =IFERROR(SUMIFS('Bid Log'!P:P,'Bid Log'!U:U,"Competition Too Strong",'Bid Log'!Q:Q,"Lost"),0) -> 0
B44: Not Qualified | F44: =COUNTIFS('Bid Log'!U:U,"Not Qualified",'Bid Log'!Q:Q,"Lost") -> 0 | H44: =IFERROR(SUMIFS('Bid Log'!P:P,'Bid Log'!U:U,"Not Qualified",'Bid Log'!Q:Q,"Lost"),0) -> 0
...

Sheet Bid Log
A1: Bid ID | B1: Project Name | C1: General Contractor | D1: Location | E1: Market Segment | F1: Scope Type | G1: Bid Stage | H1: Delivery Method | I1: Plumb Estimator | J1: HVAC Estimator | K1: Bid Received | L1: Bid Due Date | M1: Submitted Date | N1: Plumb Bid ($) | O1: HVAC Bid ($) | P1: Total Bid ($) | Q1: Status | R1: Awarded Amount | S1: Winning Competitor | T1: Competitor Amount | U1: Lost Reason | V1: Expected Award Date | W1: Probability % | X1: Next Follow-Up Date | Y1: Follow-Up Owner | Z1: Last Contact Date | AA1: Notes | AB1: Go/No-Go Score | AC1: Go/No-Go Rec | AD1: Days Pending | AE1: Follow-Up Status | AF1: Data Quality Flag
A2: ASM-2026-001 | B2: SLCC LAB Remodel | C2: Judd | E2: Professional Office | F2: Full Mechanical | G2: Hard Bid | H2: Hard Bid | I2: Patrick | J2: Stephen | K2: 46028.292 | N2: 159751 | O2: 59515 | P2: =IFERROR(IF(AND(N2="",O2=""),"",IFERROR(N2,0)+IFERROR(O2,0)),"") -> 219266 | Q2: Bid Submitted | W2: 0.5 | AA2: GCs: Judd, Stout, Rod-Lewis, Wasatch-West | AB2: =IFERROR(VLOOKUP(A2,'Go-No-Go'!$A:$M,12,0),"") -> 32 | AC2: =IFERROR(VLOOKUP(A2,'Go-No-Go'!$A:$N,14,0),"") -> Go | AD2: =IF(OR(Q2="Bid Submitted",Q2="Budget Submitted",Q2="ROM Submitted",Q2="In Progress"),IF(M2<>"",TODAY()-M2,IF(K2<>"",TODAY()-K2,"")),"") -> 126.70833 | AE2: =IF(AND(OR(Q2="Bid Submitted",Q2="Budget Submitted",Q2="ROM Submitted"),X2<>"",X2<TODAY()),"OVERDUE",IF(AND(OR(Q2="Bid Submitted",Q2="Budget Submitted",Q2="ROM Submitted"),X2<>"",X2<=TODAY()+3),"DUE SOON",IF(AND(OR(Q2="Bid Submitted",Q2="Budget Submitted",Q2="ROM Submitted"),X2=""),"MISSING","OK"))) -> MISSING | AF2: =IF(TRIM(IF(B2="","[Missing Project Name] ","")&IF(C2="","[Missing GC] ","")&IF(I2="","[Missing Plumb Estimator] ","")&IF(AND(Q2<>"In Progress",Q2<>"No Bid",Q2<>"On Hold",P2=""),"[Missing Bid Amount] ","")&IF(AND(Q2="Awarded",R2=""),"[Awarded-No Award Amount] ","")&IF(AND(Q2="Lost",U2=""),"[Lost-No Lost Reason] ","")&IF(AND(OR(Q2="Bid Submitted",Q2="Budget Submitted"),X2=""),"[Pending-No Follow-Up Date] ","")&IF(AND(OR(Q2="Bid Submitted",Q2="Budget Submitted"),Y2=""),"[Pending-No Follow-Up Owner] ","")&IF(AND(L2<>"",L2<TODAY(),OR(Q2="In Progress",Q2="")),"[Bid Due Date Passed] ",""))="","OK",TRIM(IF(B2="","[Missing Project Name] ","")&IF(C2="","[Missing GC] ","")&IF(I2="","[Missing Plumb Estimator] ","")&IF(AND(Q2<>"In Progress",Q2<>"No Bid",Q2<>"On Hold",P2=""),"[Missing Bid Amount] ","")&IF(AND(Q2="Awarded",R2=""),"[Awarded-No Award Amount] ","")&IF(AND(Q2="Lost",U2=""),"[Lost-No Lost Reason] ","")&IF(AND(OR(Q2="Bid Submitted",Q2="Budget Submitted"),X2=""),"[Pending-No Follow-Up Date] ","")&IF(AND(OR(Q2="Bid Submitted",Q2="Budget Submitted"),Y2=""),"[Pending-No Follow-Up Owner] ","")&IF(AND(L2<>"",L2<TODAY(),OR(Q2="In Progress",Q2="")),"[Bid Due Date Passed] ",""))) -> [Pending-No Follow-Up Date] [Pending-No Follow-Up Owner]
A3: ASM-2026-002 | B3: Granary Lofts | C3: Kier | E3: Multi-Family | F3: Full Mechanical | G3: Hard Bid | H3: Hard Bid | I3: Patrick | J3: Stephen | K3: 46031.292 | N3: 1271316 | O3: 1278337 | P3: =IFERROR(IF(AND(N3="",O3=""),"",IFERROR(N3,0)+IFERROR(O3,0)),"") -> 2549653 | Q3: Bid Submitted | W3: 0.5 | AA3: GC: Kier (owner-managed) | AB3: =IFERROR(VLOOKUP(A3,'Go-No-Go'!$A:$M,12,0),"") | AC3: =IFERROR(VLOOKUP(A3,'Go-No-Go'!$A:$N,14,0),"") | AD3: =IF(OR(Q3="Bid Submitted",Q3="Budget Submitted",Q3="ROM Submitted",Q3="In Progress"),IF(M3<>"",TODAY()-M3,IF(K3<>"",TODAY()-K3,"")),"") -> 123.70833 | AE3: =IF(AND(OR(Q3="Bid Submitted",Q3="Budget Submitted",Q3="ROM Submitted"),X3<>"",X3<TODAY()),"OVERDUE",IF(AND(OR(Q3="Bid Submitted",Q3="Budget Submitted",Q3="ROM Submitted"),X3<>"",X3<=TODAY()+3),"DUE SOON",IF(AND(OR(Q3="Bid Submitted",Q3="Budget Submitted",Q3="ROM Submitted"),X3=""),"MISSING","OK"))) -> MISSING | AF3: =IF(TRIM(IF(B3="","[Missing Project Name] ","")&IF(C3="","[Missing GC] ","")&IF(I3="","[Missing Plumb Estimator] ","")&IF(AND(Q3<>"In Progress",Q3<>"No Bid",Q3<>"On Hold",P3=""),"[Missing Bid Amount] ","")&IF(AND(Q3="Awarded",R3=""),"[Awarded-No Award Amount] ","")&IF(AND(Q3="Lost",U3=""),"[Lost-No Lost Reason] ","")&IF(AND(OR(Q3="Bid Submitted",Q3="Budget Submitted"),X3=""),"[Pending-No Follow-Up Date] ","")&IF(AND(OR(Q3="Bid Submitted",Q3="Budget Submitted"),Y3=""),"[Pending-No Follow-Up Owner] ","")&IF(AND(L3<>"",L3<TODAY(),OR(Q3="In Progress",Q3="")),"[Bid Due Date Passed] ",""))="","OK",TRIM(IF(B3="","[Missing Project Name] ","")&IF(C3="","[Missing GC] ","")&IF(I3="","[Missing Plumb Estimator] ","")&IF(AND(Q3<>"In Progress",Q3<>"No Bid",Q3<>"On Hold",P3=""),"[Missing Bid Amount] ","")&IF(AND(Q3="Awarded",R3=""),"[Awarded-No Award Amount] ","")&IF(AND(Q3="Lost",U3=""),"[Lost-No Lost Reason] ","")&IF(AND(OR(Q3="Bid Submitted",Q3="Budget Submitted"),X3=""),"[Pending-No Follow-Up Date] ","")&IF(AND(OR(Q3="Bid Submitted",Q3="Budget Submitted"),Y3=""),"[Pending-No Follow-Up Owner] ","")&IF(AND(L3<>"",L3<TODAY(),OR(Q3="In Progress",Q3="")),"[Bid Due Date Passed] ",""))) -> [Pending-No Follow-Up Date] [Pending-No Follow-Up Owner]
A4: ASM-2026-003 | B4: Everhome Suites | C4: Big-D | E4: Hotel / Resort | F4: Full Mechanical | G4: Hard Bid | H4: Hard Bid | I4: Patrick | J4: Stephen | K4: 46035.292 | N4: 1469827 | O4: 809252 | P4: =IFERROR(IF(AND(N4="",O4=""),"",IFERROR(N4,0)+IFERROR(O4,0)),"") -> 2279079 | Q4: Lost | T4: 1972079 | W4: 0 | Z4: 46147.25 | AA4: GCs: Big-D, Zwick, R&O | AB4: =IFERROR(VLOOKUP(A4,'Go-No-Go'!$A:$M,12,0),"") -> 30 | AC4: =IFERROR(VLOOKUP(A4,'Go-No-Go'!$A:$N,14,0),"") -> Go | AD4: =IF(OR(Q4="Bid Submitted",Q4="Budget Submitted",Q4="ROM Submitted",Q4="In Progress"),IF(M4<>"",TODAY()-M4,IF(K4<>"",TODAY()-K4,"")),"") | AE4: =IF(AND(OR(Q4="Bid Submitted",Q4="Budget Submitted",Q4="ROM Submitted"),X4<>"",X4<TODAY()),"OVERDUE",IF(AND(OR(Q4="Bid Submitted",Q4="Budget Submitted",Q4="ROM Submitted"),X4<>"",X4<=TODAY()+3),"DUE SOON",IF(AND(OR(Q4="Bid Submitted",Q4="Budget Submitted",Q4="ROM Submitted"),X4=""),"MISSING","OK"))) -> OK | AF4: =IF(TRIM(IF(B4="","[Missing Project Name] ","")&IF(C4="","[Missing GC] ","")&IF(I4="","[Missing Plumb Estimator] ","")&IF(AND(Q4<>"In Progress",Q4<>"No Bid",Q4<>"On Hold",P4=""),"[Missing Bid Amount] ","")&IF(AND(Q4="Awarded",R4=""),"[Awarded-No Award Amount] ","")&IF(AND(Q4="Lost",U4=""),"[Lost-No Lost Reason] ","")&IF(AND(OR(Q4="Bid Submitted",Q4="Budget Submitted"),X4=""),"[Pending-No Follow-Up Date] ","")&IF(AND(OR(Q4="Bid Submitted",Q4="Budget Submitted"),Y4=""),"[Pending-No Follow-Up Owner] ","")&IF(AND(L4<>"",L4<TODAY(),OR(Q4="In Progress",Q4="")),"[Bid Due Date Passed] ",""))="","OK",TRIM(IF(B4="","[Missing Project Name] ","")&IF(C4="","[Missing GC] ","")&IF(I4="","[Missing Plumb Estimator] ","")&IF(AND(Q4<>"In Progress",Q4<>"No Bid",Q4<>"On Hold",P4=""),"[Missing Bid Amount] ","")&IF(AND(Q4="Awarded",R4=""),"[Awarded-No Award Amount] ","")&IF(AND(Q4="Lost",U4=""),"[Lost-No Lost Reason] ","")&IF(AND(OR(Q4="Bid Submitted",Q4="Budget Submitted"),X4=""),"[Pending-No Follow-Up Date] ","")&IF(AND(OR(Q4="Bid Submitted",Q4="Budget Submitted"),Y4=""),"[Pending-No Follow-Up Owner] ","")&IF(AND(L4<>"",L4<TODAY(),OR(Q4="In Progress",Q4="")),"[Bid Due Date Passed] ",""))) -> [Lost-No Lost Reason]
A5: ASM-2026-004 | B5: Bluffdale City Admin | C5: Rod-Lewis | D5: Bluffdale, UT | E5: Municipal | F5: Full Mechanical | G5: Hard Bid | H5: Hard Bid | I5: Patrick | J5: Stephen | K5: 46037.292 | N5: 223680 | O5: 92569 | P5: =IFERROR(IF(AND(N5="",O5=""),"",IFERROR(N5,0)+IFERROR(O5,0)),"") -> 316249 | Q5: Bid Submitted | W5: 0.5 | AA5: GCs: Rod-Lewis, Judd, Mahas, Bailey, Silverleaf | AB5: =IFERROR(VLOOKUP(A5,'Go-No-Go'!$A:$M,12,0),"") | AC5: =IFERROR(VLOOKUP(A5,'Go-No-Go'!$A:$N,14,0),"") | AD5: =IF(OR(Q5="Bid Submitted",Q5="Budget Submitted",Q5="ROM Submitted",Q5="In Progress"),IF(M5<>"",TODAY()-M5,IF(K5<>"",TODAY()-K5,"")),"") -> 117.70833 | AE5: =IF(AND(OR(Q5="Bid Submitted",Q5="Budget Submitted",Q5="ROM Submitted"),X5<>"",X5<TODAY()),"OVERDUE",IF(AND(OR(Q5="Bid Submitted",Q5="Budget Submitted",Q5="ROM Submitted"),X5<>"",X5<=TODAY()+3),"DUE SOON",IF(AND(OR(Q5="Bid Submitted",Q5="Budget Submitted",Q5="ROM Submitted"),X5=""),"MISSING","OK"))) -> MISSING | AF5: =IF(TRIM(IF(B5="","[Missing Project Name] ","")&IF(C5="","[Missing GC] ","")&IF(I5="","[Missing Plumb Estimator] ","")&IF(AND(Q5<>"In Progress",Q5<>"No Bid",Q5<>"On Hold",P5=""),"[Missing Bid Amount] ","")&IF(AND(Q5="Awarded",R5=""),"[Awarded-No Award Amount] ","")&IF(AND(Q5="Lost",U5=""),"[Lost-No Lost Reason] ","")&IF(AND(OR(Q5="Bid Submitted",Q5="Budget Submitted"),X5=""),"[Pending-No Follow-Up Date] ","")&IF(AND(OR(Q5="Bid Submitted",Q5="Budget Submitted"),Y5=""),"[Pending-No Follow-Up Owner] ","")&IF(AND(L5<>"",L5<TODAY(),OR(Q5="In Progress",Q5="")),"[Bid Due Date Passed] ",""))="","OK",TRIM(IF(B5="","[Missing Project Name] ","")&IF(C5="","[Missing GC] ","")&IF(I5="","[Missing Plumb Estimator] ","")&IF(AND(Q5<>"In Progress",Q5<>"No Bid",Q5<>"On Hold",P5=""),"[Missing Bid Amount] ","")&IF(AND(Q5="Awarded",R5=""),"[Awarded-No Award Amount] ","")&IF(AND(Q5="Lost",U5=""),"[Lost-No Lost Reason] ","")&IF(AND(OR(Q5="Bid Submitted",Q5="Budget Submitted"),X5=""),"[Pending-No Follow-Up Date] ","")&IF(AND(OR(Q5="Bid Submitted",Q5="Budget Submitted"),Y5=""),"[Pending-No Follow-Up Owner] ","")&IF(AND(L5<>"",L5<TODAY(),OR(Q5="In Progress",Q5="")),"[Bid Due Date Passed] ",""))) -> [Pending-No Follow-Up Date] [Pending-No Follow-Up Owner]
A6: ASM-2026-005 | B6: Crown Apt Remodel | C6: Lotus | E6: Multi-Family | F6: Full Mechanical | G6: Hard Bid | H6: Hard Bid | I6: Patrick | J6: Stephen | K6: 46043.292 | N6: 390920 | O6: 340868 | P6: =IFERROR(IF(AND(N6="",O6=""),"",IFERROR(N6,0)+IFERROR(O6,0)),"") -> 731788 | Q6: Bid Submitted | W6: 0.5 | AB6: =IFERROR(VLOOKUP(A6,'Go-No-Go'!$A:$M,12,0),"") -> 36 | AC6: =IFERROR(VLOOKUP(A6,'Go-No-Go'!$A:$N,14,0),"") -> Go | AD6: =IF(OR(Q6="Bid Submitted",Q6="Budget Submitted",Q6="ROM Submitted",Q6="In Progress"),IF(M6<>"",TODAY()-M6,IF(K6<>"",TODAY()-K6,"")),"") -> 111.70833 | AE6: =IF(AND(OR(Q6="Bid Submitted",Q6="Budget Submitted",Q6="ROM Submitted"),X6<>"",X6<TODAY()),"OVERDUE",IF(AND(OR(Q6="Bid Submitted",Q6="Budget Submitted",Q6="ROM Submitted"),X6<>"",X6<=TODAY()+3),"DUE SOON",IF(AND(OR(Q6="Bid Submitted",Q6="Budget Submitted",Q6="ROM Submitted"),X6=""),"MISSING","OK"))) -> MISSING | AF6: =IF(TRIM(IF(B6="","[Missing Project Name] ","")&IF(C6="","[Missing GC] ","")&IF(I6="","[Missing Plumb Estimator] ","")&IF(AND(Q6<>"In Progress",Q6<>"No Bid",Q6<>"On Hold",P6=""),"[Missing Bid Amount] ","")&IF(AND(Q6="Awarded",R6=""),"[Awarded-No Award Amount] ","")&IF(AND(Q6="Lost",U6=""),"[Lost-No Lost Reason] ","")&IF(AND(OR(Q6="Bid Submitted",Q6="Budget Submitted"),X6=""),"[Pending-No Follow-Up Date] ","")&IF(AND(OR(Q6="Bid Submitted",Q6="Budget Submitted"),Y6=""),"[Pending-No Follow-Up Owner] ","")&IF(AND(L6<>"",L6<TODAY(),OR(Q6="In Progress",Q6="")),"[Bid Due Date Passed] ",""))="","OK",TRIM(IF(B6="","[Missing Project Name] ","")&IF(C6="","[Missing GC] ","")&IF(I6="","[Missing Plumb Estimator] ","")&IF(AND(Q6<>"In Progress",Q6<>"No Bid",Q6<>"On Hold",P6=""),"[Missing Bid Amount] ","")&IF(AND(Q6="Awarded",R6=""),"[Awarded-No Award Amount] ","")&IF(AND(Q6="Lost",U6=""),"[Lost-No Lost Reason] ","")&IF(AND(OR(Q6="Bid Submitted",Q6="Budget Submitted"),X6=""),"[Pending-No Follow-Up Date] ","")&IF(AND(OR(Q6="Bid Submitted",Q6="Budget Submitted"),Y6=""),"[Pending-No Follow-Up Owner] ","")&IF(AND(L6<>"",L6<TODAY(),OR(Q6="In Progress",Q6="")),"[Bid Due Date Passed] ",""))) -> [Pending-No Follow-Up Date] [Pending-No Follow-Up Owner]
A7: ASM-2026-006 | B7: The Collective @ Morning Vista | C7: Robinson | E7: Multi-Family | F7: Full Mechanical | G7: Hard Bid | H7: Hard Bid | I7: Patrick | J7: Stephen | K7: 46043.292 | N7: 1330294 | O7: 880986 | P7: =IFERROR(IF(AND(N7="",O7=""),"",IFERROR(N7,0)+IFERROR(O7,0)),"") -> 2211280 | Q7: Bid Submitted | W7: 0.5 | AA7: GCs: Robinson, R&O | AB7: =IFERROR(VLOOKUP(A7,'Go-No-Go'!$A:$M,12,0),"") | AC7: =IFERROR(VLOOKUP(A7,'Go-No-Go'!$A:$N,14,0),"") | AD7: =IF(OR(Q7="Bid Submitted",Q7="Budget Submitted",Q7="ROM Submitted",Q7="In Progress"),IF(M7<>"",TODAY()-M7,IF(K7<>"",TODAY()-K7,"")),"") -> 111.70833 | AE7: =IF(AND(OR(Q7="Bid Submitted",Q7="Budget Submitted",Q7="ROM Submitted"),X7<>"",X7<TODAY()),"OVERDUE",IF(AND(OR(Q7="Bid Submitted",Q7="Budget Submitted",Q7="ROM Submitted"),X7<>"",X7<=TODAY()+3),"DUE SOON",IF(AND(OR(Q7="Bid Submitted",Q7="Budget Submitted",Q7="ROM Submitted"),X7=""),"MISSING","OK"))) -> MISSING | AF7: =IF(TRIM(IF(B7="","[Missing Project Name] ","")&IF(C7="","[Missing GC] ","")&IF(I7="","[Missing Plumb Estimator] ","")&IF(AND(Q7<>"In Progress",Q7<>"No Bid",Q7<>"On Hold",P7=""),"[Missing Bid Amount] ","")&IF(AND(Q7="Awarded",R7=""),"[Awarded-No Award Amount] ","")&IF(AND(Q7="Lost",U7=""),"[Lost-No Lost Reason] ","")&IF(AND(OR(Q7="Bid Submitted",Q7="Budget Submitted"),X7=""),"[Pending-No Follow-Up Date] ","")&IF(AND(OR(Q7="Bid Submitted",Q7="Budget Submitted"),Y7=""),"[Pending-No Follow-Up Owner] ","")&IF(AND(L7<>"",L7<TODAY(),OR(Q7="In Progress",Q7="")),"[Bid Due Date Passed] ",""))="","OK",TRIM(IF(B7="","[Missing Project Name] ","")&IF(C7="","[Missing GC] ","")&IF(I7="","[Missing Plumb Estimator] ","")&IF(AND(Q7<>"In Progress",Q7<>"No Bid",Q7<>"On Hold",P7=""),"[Missing Bid Amount] ","")&IF(AND(Q7="Awarded",R7=""),"[Awarded-No Award Amount] ","")&IF(AND(Q7="Lost",U7=""),"[Lost-No Lost Reason] ","")&IF(AND(OR(Q7="Bid Submitted",Q7="Budget Submitted"),X7=""),"[Pending-No Follow-Up Date] ","")&IF(AND(OR(Q7="Bid Submitted",Q7="Budget Submitted"),Y7=""),"[Pending-No Follow-Up Owner] ","")&IF(AND(L7<>"",L7<TODAY(),OR(Q7="In Progress",Q7="")),"[Bid Due Date Passed] ",""))) -> [Pending-No Follow-Up Date] [Pending-No Follow-Up Owner]
A8: ASM-2026-007 | B8: Jordan Valley Lots 8, 9, 10 | C8: BCC | D8: West Jordan, UT | E8: Multi-Family | F8: Full Mechanical | G8: Hard Bid | H8: Hard Bid | I8: Patrick | J8: Stephen | K8: 46044.292 | N8: 6376876 | O8: 6874008 | P8: =IFERROR(IF(AND(N8="",O8=""),"",IFERROR(N8,0)+IFERROR(O8,0)),"") -> 13250884 | Q8: Bid Submitted | W8: 0.5 | AA8: GC: BCC | AB8: =IFERROR(VLOOKUP(A8,'Go-No-Go'!$A:$M,12,0),"") -> 26 | AC8: =IFERROR(VLOOKUP(A8,'Go-No-Go'!$A:$N,14,0),"") -> Review | AD8: =IF(OR(Q8="Bid Submitted",Q8="Budget Submitted",Q8="ROM Submitted",Q8="In Progress"),IF(M8<>"",TODAY()-M8,IF(K8<>"",TODAY()-K8,"")),"") -> 110.70833 | AE8: =IF(AND(OR(Q8="Bid Submitted",Q8="Budget Submitted",Q8="ROM Submitted"),X8<>"",X8<TODAY()),"OVERDUE",IF(AND(OR(Q8="Bid Submitted",Q8="Budget Submitted",Q8="ROM Submitted"),X8<>"",X8<=TODAY()+3),"DUE SOON",IF(AND(OR(Q8="Bid Submitted",Q8="Budget Submitted",Q8="ROM Submitted"),X8=""),"MISSING","OK"))) -> MISSING | AF8: =IF(TRIM(IF(B8="","[Missing Project Name] ","")&IF(C8="","[Missing GC] ","")&IF(I8="","[Missing Plumb Estimator] ","")&IF(AND(Q8<>"In Progress",Q8<>"No Bid",Q8<>"On Hold",P8=""),"[Missing Bid Amount] ","")&IF(AND(Q8="Awarded",R8=""),"[Awarded-No Award Amount] ","")&IF(AND(Q8="Lost",U8=""),"[Lost-No Lost Reason] ","")&IF(AND(OR(Q8="Bid Submitted",Q8="Budget Submitted"),X8=""),"[Pending-No Follow-Up Date] ","")&IF(AND(OR(Q8="Bid Submitted",Q8="Budget Submitted"),Y8=""),"[Pending-No Follow-Up Owner] ","")&IF(AND(L8<>"",L8<TODAY(),OR(Q8="In Progress",Q8="")),"[Bid Due Date Passed] ",""))="","OK",TRIM(IF(B8="","[Missing Project Name] ","")&IF(C8="","[Missing GC] ","")&IF(I8="","[Missing Plumb Estimator] ","")&IF(AND(Q8<>"In Progress",Q8<>"No Bid",Q8<>"On Hold",P8=""),"[Missing Bid Amount] ","")&IF(AND(Q8="Awarded",R8=""),"[Awarded-No Award Amount] ","")&IF(AND(Q8="Lost",U8=""),"[Lost-No Lost Reason] ","")&IF(AND(OR(Q8="Bid Submitted",Q8="Budget Submitted"),X8=""),"[Pending-No Follow-Up Date] ","")&IF(AND(OR(Q8="Bid Submitted",Q8="Budget Submitted"),Y8=""),"[Pending-No Follow-Up Owner] ","")&IF(AND(L8<>"",L8<TODAY(),OR(Q8="In Progress",Q8="")),"[Bid Due Date Passed] ",""))) -> [Pending-No Follow-Up Date] [Pending-No Follow-Up Owner]
A9: ASM-2026-008 | B9: Pacific Yard Apt | C9: Kier | E9: Multi-Family | F9: Full Mechanical | G9: Hard Bid | H9: Hard Bid | I9: Patrick | J9: Stephen | K9: 46058.292 | N9: 5398931 | O9: 4298204 | P9: =IFERROR(IF(AND(N9="",O9=""),"",IFERROR(N9,0)+IFERROR(O9,0)),"") -> 9697135 | Q9: Bid Submitted | W9: 0.5 | AA9: GCs: Kier, Headwaters, RVC | AB9: =IFERROR(VLOOKUP(A9,'Go-No-Go'!$A:$M,12,0),"") | AC9: =IFERROR(VLOOKUP(A9,'Go-No-Go'!$A:$N,14,0),"") | AD9: =IF(OR(Q9="Bid Submitted",Q9="Budget Submitted",Q9="ROM Submitted",Q9="In Progress"),IF(M9<>"",TODAY()-M9,IF(K9<>"",TODAY()-K9,"")),"") -> 96.708333 | AE9: =IF(AND(OR(Q9="Bid Submitted",Q9="Budget Submitted",Q9="ROM Submitted"),X9<>"",X9<TODAY()),"OVERDUE",IF(AND(OR(Q9="Bid Submitted",Q9="Budget Submitted",Q9="ROM Submitted"),X9<>"",X9<=TODAY()+3),"DUE SOON",IF(AND(OR(Q9="Bid Submitted",Q9="Budget Submitted",Q9="ROM Submitted"),X9=""),"MISSING","OK"))) -> MISSING | AF9: =IF(TRIM(IF(B9="","[Missing Project Name] ","")&IF(C9="","[Missing GC] ","")&IF(I9="","[Missing Plumb Estimator] ","")&IF(AND(Q9<>"In Progress",Q9<>"No Bid",Q9<>"On Hold",P9=""),"[Missing Bid Amount] ","")&IF(AND(Q9="Awarded",R9=""),"[Awarded-No Award Amount] ","")&IF(AND(Q9="Lost",U9=""),"[Lost-No Lost Reason] ","")&IF(AND(OR(Q9="Bid Submitted",Q9="Budget Submitted"),X9=""),"[Pending-No Follow-Up Date] ","")&IF(AND(OR(Q9="Bid Submitted",Q9="Budget Submitted"),Y9=""),"[Pending-No Follow-Up Owner] ","")&IF(AND(L9<>"",L9<TODAY(),OR(Q9="In Progress",Q9="")),"[Bid Due Date Passed] ",""))="","OK",TRIM(IF(B9="","[Missing Project Name] ","")&IF(C9="","[Missing GC] ","")&IF(I9="","[Missing Plumb Estimator] ","")&IF(AND(Q9<>"In Progress",Q9<>"No Bid",Q9<>"On Hold",P9=""),"[Missing Bid Amount] ","")&IF(AND(Q9="Awarded",R9=""),"[Awarded-No Award Amount] ","")&IF(AND(Q9="Lost",U9=""),"[Lost-No Lost Reason] ","")&IF(AND(OR(Q9="Bid Submitted",Q9="Budget Submitted"),X9=""),"[Pending-No Follow-Up Date] ","")&IF(AND(OR(Q9="Bid Submitted",Q9="Budget Submitted"),Y9=""),"[Pending-No Follow-Up Owner] ","")&IF(AND(L9<>"",L9<TODAY(),OR(Q9="In Progress",Q9="")),"[Bid Due Date Passed] ",""))) -> [Pending-No Follow-Up Date] [Pending-No Follow-Up Owner]
A10: ASM-2026-009 | B10: Antelope Station | C10: Revival Development | E10: Municipal | F10: Full Mechanical | G10: Hard Bid | H10: Hard Bid | I10: Patrick | J10: Stephen | K10: 46050.292 | N10: 43556 | O10: 80889 | P10: =IFERROR(IF(AND(N10="",O10=""),"",IFERROR(N10,0)+IFERROR(O10,0)),"") -> 124445 | Q10: Bid Submitted | W10: 0.5 | AB10: =IFERROR(VLOOKUP(A10,'Go-No-Go'!$A:$M,12,0),"") -> 29 | AC10: =IFERROR(VLOOKUP(A10,'Go-No-Go'!$A:$N,14,0),"") -> Go | AD10: =IF(OR(Q10="Bid Submitted",Q10="Budget Submitted",Q10="ROM Submitted",Q10="In Progress"),IF(M10<>"",TODAY()-M10,IF(K10<>"",TODAY()-K10,"")),"") -> 104.70833 | AE10: =IF(AND(OR(Q10="Bid Submitted",Q10="Budget Submitted",Q10="ROM Submitted"),X10<>"",X10<TODAY()),"OVERDUE",IF(AND(OR(Q10="Bid Submitted",Q10="Budget Submitted",Q10="ROM Submitted"),X10<>"",X10<=TODAY()+3),"DUE SOON",IF(AND(OR(Q10="Bid Submitted",Q10="Budget Submitted",Q10="ROM Submitted"),X10=""),"MISSING","OK"))) -> MISSING | AF10: =IF(TRIM(IF(B10="","[Missing Project Name] ","")&IF(C10="","[Missing GC] ","")&IF(I10="","[Missing Plumb Estimator] ","")&IF(AND(Q10<>"In Progress",Q10<>"No Bid",Q10<>"On Hold",P10=""),"[Missing Bid Amount] ","")&IF(AND(Q10="Awarded",R10=""),"[Awarded-No Award Amount] ","")&IF(AND(Q10="Lost",U10=""),"[Lost-No Lost Reason] ","")&IF(AND(OR(Q10="Bid Submitted",Q10="Budget Submitted"),X10=""),"[Pending-No Follow-Up Date] ","")&IF(AND(OR(Q10="Bid Submitted",Q10="Budget Submitted"),Y10=""),"[Pending-No Follow-Up Owner] ","")&IF(AND(L10<>"",L10<TODAY(),OR(Q10="In Progress",Q10="")),"[Bid Due Date Passed] ",""))="","OK",TRIM(IF(B10="","[Missing Project Name] ","")&IF(C10="","[Missing GC] ","")&IF(I10="","[Missing Plumb Estimator] ","")&IF(AND(Q10<>"In Progress",Q10<>"No Bid",Q10<>"On Hold",P10=""),"[Missing Bid Amount] ","")&IF(AND(Q10="Awarded",R10=""),"[Awarded-No Award Amount] ","")&IF(AND(Q10="Lost",U10=""),"[Lost-No Lost Reason] ","")&IF(AND(OR(Q10="Bid Submitted",Q10="Budget Submitted"),X10=""),"[Pending-No Follow-Up Date] ","")&IF(AND(OR(Q10="Bid Submitted",Q10="Budget Submitted"),Y10=""),"[Pending-No Follow-Up Owner] ","")&IF(AND(L10<>"",L10<TODAY(),OR(Q10="In Progress",Q10="")),"[Bid Due Date Passed] ",""))) -> [Pending-No Follow-Up Date] [Pending-No Follow-Up Owner]
A11: ASM-2026-010 | B11: Red Sky Apt | C11: BCC | E11: Multi-Family | F11: Full Mechanical | G11: Hard Bid | H11: Hard Bid | I11: Patrick | J11: Stephen | K11: 46056.292 | N11: 3166896 | O11: 3511430 | P11: =IFERROR(IF(AND(N11="",O11=""),"",IFERROR(N11,0)+IFERROR(O11,0)),"") -> 6678326 | Q11: Bid Submitted | W11: 0.5 | AA11: GC: BCC (owner-managed) | AB11: =IFERROR(VLOOKUP(A11,'Go-No-Go'!$A:$M,12,0),"") | AC11: =IFERROR(VLOOKUP(A11,'Go-No-Go'!$A:$N,14,0),"") | AD11: =IF(OR(Q11="Bid Submitted",Q11="Budget Submitted",Q11="ROM Submitted",Q11="In Progress"),IF(M11<>"",TODAY()-M11,IF(K11<>"",TODAY()-K11,"")),"") -> 98.708333 | AE11: =IF(AND(OR(Q11="Bid Submitted",Q11="Budget Submitted",Q11="ROM Submitted"),X11<>"",X11<TODAY()),"OVERDUE",IF(AND(OR(Q11="Bid Submitted",Q11="Budget Submitted",Q11="ROM Submitted"),X11<>"",X11<=TODAY()+3),"DUE SOON",IF(AND(OR(Q11="Bid Submitted",Q11="Budget Submitted",Q11="ROM Submitted"),X11=""),"MISSING","OK"))) -> MISSING | AF11: =IF(TRIM(IF(B11="","[Missing Project Name] ","")&IF(C11="","[Missing GC] ","")&IF(I11="","[Missing Plumb Estimator] ","")&IF(AND(Q11<>"In Progress",Q11<>"No Bid",Q11<>"On Hold",P11=""),"[Missing Bid Amount] ","")&IF(AND(Q11="Awarded",R11=""),"[Awarded-No Award Amount] ","")&IF(AND(Q11="Lost",U11=""),"[Lost-No Lost Reason] ","")&IF(AND(OR(Q11="Bid Submitted",Q11="Budget Submitted"),X11=""),"[Pending-No Follow-Up Date] ","")&IF(AND(OR(Q11="Bid Submitted",Q11="Budget Submitted"),Y11=""),"[Pending-No Follow-Up Owner] ","")&IF(AND(L11<>"",L11<TODAY(),OR(Q11="In Progress",Q11="")),"[Bid Due Date Passed] ",""))="","OK",TRIM(IF(B11="","[Missing Project Name] ","")&IF(C11="","[Missing GC] ","")&IF(I11="","[Missing Plumb Estimator] ","")&IF(AND(Q11<>"In Progress",Q11<>"No Bid",Q11<>"On Hold",P11=""),"[Missing Bid Amount] ","")&IF(AND(Q11="Awarded",R11=""),"[Awarded-No Award Amount] ","")&IF(AND(Q11="Lost",U11=""),"[Lost-No Lost Reason] ","")&IF(AND(OR(Q11="Bid Submitted",Q11="Budget Submitted"),X11=""),"[Pending-No Follow-Up Date] ","")&IF(AND(OR(Q11="Bid Submitted",Q11="Budget Submitted"),Y11=""),"[Pending-No Follow-Up Owner] ","")&IF(AND(L11<>"",L11<TODAY(),OR(Q11="In Progress",Q11="")),"[Bid Due Date Passed] ",""))) -> [Pending-No Follow-Up Date] [Pending-No Follow-Up Owner]
A12: ASM-2026-011 | B12: HH Parking Structure | C12: Wadman | E12: Professional Office | F12: Plumbing Only | G12: Hard Bid | H12: Hard Bid | I12: Patrick | J12: No Bid | K12: 46051.292 | N12: 167139 | P12: =IFERROR(IF(AND(N12="",O12=""),"",IFERROR(N12,0)+IFERROR(O12,0)),"") -> 167139 | Q12: Bid Submitted | W12: 0.5 | AA12: GCs: Wadman, Forge | AB12: =IFERROR(VLOOKUP(A12,'Go-No-Go'!$A:$M,12,0),"") -> 26 | AC12: =IFERROR(VLOOKUP(A12,'Go-No-Go'!$A:$N,14,0),"") -> Review | AD12: =IF(OR(Q12="Bid Submitted",Q12="Budget Submitted",Q12="ROM Submitted",Q12="In Progress"),IF(M12<>"",TODAY()-M12,IF(K12<>"",TODAY()-K12,"")),"") -> 103.70833 | AE12: =IF(AND(OR(Q12="Bid Submitted",Q12="Budget Submitted",Q12="ROM Submitted"),X12<>"",X12<TODAY()),"OVERDUE",IF(AND(OR(Q12="Bid Submitted",Q12="Budget Submitted",Q12="ROM Submitted"),X12<>"",X12<=TODAY()+3),"DUE SOON",IF(AND(OR(Q12="Bid Submitted",Q12="Budget Submitted",Q12="ROM Submitted"),X12=""),"MISSING","OK"))) -> MISSING | AF12: =IF(TRIM(IF(B12="","[Missing Project Name] ","")&IF(C12="","[Missing GC] ","")&IF(I12="","[Missing Plumb Estimator] ","")&IF(AND(Q12<>"In Progress",Q12<>"No Bid",Q12<>"On Hold",P12=""),"[Missing Bid Amount] ","")&IF(AND(Q12="Awarded",R12=""),"[Awarded-No Award Amount] ","")&IF(AND(Q12="Lost",U12=""),"[Lost-No Lost Reason] ","")&IF(AND(OR(Q12="Bid Submitted",Q12="Budget Submitted"),X12=""),"[Pending-No Follow-Up Date] ","")&IF(AND(OR(Q12="Bid Submitted",Q12="Budget Submitted"),Y12=""),"[Pending-No Follow-Up Owner] ","")&IF(AND(L12<>"",L12<TODAY(),OR(Q12="In Progress",Q12="")),"[Bid Due Date Passed] ",""))="","OK",TRIM(IF(B12="","[Missing Project Name] ","")&IF(C12="","[Missing GC] ","")&IF(I12="","[Missing Plumb Estimator] ","")&IF(AND(Q12<>"In Progress",Q12<>"No Bid",Q12<>"On Hold",P12=""),"[Missing Bid Amount] ","")&IF(AND(Q12="Awarded",R12=""),"[Awarded-No Award Amount] ","")&IF(AND(Q12="Lost",U12=""),"[Lost-No Lost Reason] ","")&IF(AND(OR(Q12="Bid Submitted",Q12="Budget Submitted"),X12=""),"[Pending-No Follow-Up Date] ","")&IF(AND(OR(Q12="Bid Submitted",Q12="Budget Submitted"),Y12=""),"[Pending-No Follow-Up Owner] ","")&IF(AND(L12<>"",L12<TODAY(),OR(Q12="In Progress",Q12="")),"[Bid Due Date Passed] ",""))) -> [Pending-No Follow-Up Date] [Pending-No Follow-Up Owner]
A13: ASM-2026-012 | B13: The Royce | C13: Wadman | E13: Multi-Family | F13: Full Mechanical | G13: Hard Bid | H13: Hard Bid | I13: Patrick | J13: Stephen | K13: 46051.292 | N13: 4134360 | O13: 4534706 | P13: =IFERROR(IF(AND(N13="",O13=""),"",IFERROR(N13,0)+IFERROR(O13,0)),"") -> 8669066 | Q13: Bid Submitted | W13: 0.5 | AA13: GC: Wadman | AB13: =IFERROR(VLOOKUP(A13,'Go-No-Go'!$A:$M,12,0),"") -> 29 | AC13: =IFERROR(VLOOKUP(A13,'Go-No-Go'!$A:$N,14,0),"") -> Go | AD13: =IF(OR(Q13="Bid Submitted",Q13="Budget Submitted",Q13="ROM Submitted",Q13="In Progress"),IF(M13<>"",TODAY()-M13,IF(K13<>"",TODAY()-K13,"")),"") -> 103.70833 | AE13: =IF(AND(OR(Q13="Bid Submitted",Q13="Budget Submitted",Q13="ROM Submitted"),X13<>"",X13<TODAY()),"OVERDUE",IF(AND(OR(Q13="Bid Submitted",Q13="Budget Submitted",Q13="ROM Submitted"),X13<>"",X13<=TODAY()+3),"DUE SOON",IF(AND(OR(Q13="Bid Submitted",Q13="Budget Submitted",Q13="ROM Submitted"),X13=""),"MISSING","OK"))) -> MISSING | AF13: =IF(TRIM(IF(B13="","[Missing Project Name] ","")&IF(C13="","[Missing GC] ","")&IF(I13="","[Missing Plumb Estimator] ","")&IF(AND(Q13<>"In Progress",Q13<>"No Bid",Q13<>"On Hold",P13=""),"[Missing Bid Amount] ","")&IF(AND(Q13="Awarded",R13=""),"[Awarded-No Award Amount] ","")&IF(AND(Q13="Lost",U13=""),"[Lost-No Lost Reason] ","")&IF(AND(OR(Q13="Bid Submitted",Q13="Budget Submitted"),X13=""),"[Pending-No Follow-Up Date] ","")&IF(AND(OR(Q13="Bid Submitted",Q13="Budget Submitted"),Y13=""),"[Pending-No Follow-Up Owner] ","")&IF(AND(L13<>"",L13<TODAY(),OR(Q13="In Progress",Q13="")),"[Bid Due Date Passed] ",""))="","OK",TRIM(IF(B13="","[Missing Project Name] ","")&IF(C13="","[Missing GC] ","")&IF(I13="","[Missing Plumb Estimator] ","")&IF(AND(Q13<>"In Progress",Q13<>"No Bid",Q13<>"On Hold",P13=""),"[Missing Bid Amount] ","")&IF(AND(Q13="Awarded",R13=""),"[Awarded-No Award Amount] ","")&IF(AND(Q13="Lost",U13=""),"[Lost-No Lost Reason] ","")&IF(AND(OR(Q13="Bid Submitted",Q13="Budget Submitted"),X13=""),"[Pending-No Follow-Up Date] ","")&IF(AND(OR(Q13="Bid Submitted",Q13="Budget Submitted"),Y13=""),"[Pending-No Follow-Up Owner] ","")&IF(AND(L13<>"",L13<TODAY(),OR(Q13="In Progress",Q13="")),"[Bid Due Date Passed] ",""))) -> [Pending-No Follow-Up Date] [Pending-No Follow-Up Owner]
A14: ASM-2026-013 | B14: Crossroads Urban Center | C14: Cameron | E14: Professional Office | F14: Full Mechanical | G14: Hard Bid | H14: Hard Bid | I14: Patrick | J14: Stephen | K14: 46058.292 | N14: 205754 | O14: 130206 | P14: =IFERROR(IF(AND(N14="",O14=""),"",IFERROR(N14,0)+IFERROR(O14,0)),"") -> 335960 | Q14: Bid Submitted | W14: 0.5 | AA14: GC: Cameron | AB14: =IFERROR(VLOOKUP(A14,'Go-No-Go'!$A:$M,12,0),"") -> 30 | AC14: =IFERROR(VLOOKUP(A14,'Go-No-Go'!$A:$N,14,0),"") -> Go | AD14: =IF(OR(Q14="Bid Submitted",Q14="Budget Submitted",Q14="ROM Submitted",Q14="In Progress"),IF(M14<>"",TODAY()-M14,IF(K14<>"",TODAY()-K14,"")),"") -> 96.708333 | AE14: =IF(AND(OR(Q14="Bid Submitted",Q14="Budget Submitted",Q14="ROM Submitted"),X14<>"",X14<TODAY()),"OVERDUE",IF(AND(OR(Q14="Bid Submitted",Q14="Budget Submitted",Q14="ROM Submitted"),X14<>"",X14<=TODAY()+3),"DUE SOON",IF(AND(OR(Q14="Bid Submitted",Q14="Budget Submitted",Q14="ROM Submitted"),X14=""),"MISSING","OK"))) -> MISSING | AF14: =IF(TRIM(IF(B14="","[Missing Project Name] ","")&IF(C14="","[Missing GC] ","")&IF(I14="","[Missing Plumb Estimator] ","")&IF(AND(Q14<>"In Progress",Q14<>"No Bid",Q14<>"On Hold",P14=""),"[Missing Bid Amount] ","")&IF(AND(Q14="Awarded",R14=""),"[Awarded-No Award Amount] ","")&IF(AND(Q14="Lost",U14=""),"[Lost-No Lost Reason] ","")&IF(AND(OR(Q14="Bid Submitted",Q14="Budget Submitted"),X14=""),"[Pending-No Follow-Up Date] ","")&IF(AND(OR(Q14="Bid Submitted",Q14="Budget Submitted"),Y14=""),"[Pending-No Follow-Up Owner] ","")&IF(AND(L14<>"",L14<TODAY(),OR(Q14="In Progress",Q14="")),"[Bid Due Date Passed] ",""))="","OK",TRIM(IF(B14="","[Missing Project Name] ","")&IF(C14="","[Missing GC] ","")&IF(I14="","[Missing Plumb Estimator] ","")&IF(AND(Q14<>"In Progress",Q14<>"No Bid",Q14<>"On Hold",P14=""),"[Missing Bid Amount] ","")&IF(AND(Q14="Awarded",R14=""),"[Awarded-No Award Amount] ","")&IF(AND(Q14="Lost",U14=""),"[Lost-No Lost Reason] ","")&IF(AND(OR(Q14="Bid Submitted",Q14="Budget Submitted"),X14=""),"[Pending-No Follow-Up Date] ","")&IF(AND(OR(Q14="Bid Submitted",Q14="Budget Submitted"),Y14=""),"[Pending-No Follow-Up Owner] ","")&IF(AND(L14<>"",L14<TODAY(),OR(Q14="In Progress",Q14="")),"[Bid Due Date Passed] ",""))) -> [Pending-No Follow-Up Date] [Pending-No Follow-Up Owner]
A15: ASM-2026-014 | B15: Mojave Crossing | C15: EK Bailey | E15: Multi-Family | F15: Full Mechanical | G15: Hard Bid | H15: Hard Bid | I15: Patrick | J15: Stephen | K15: 46049.292 | N15: 1332893 | O15: 778874 | P15: =IFERROR(IF(AND(N15="",O15=""),"",IFERROR(N15,0)+IFERROR(O15,0)),"") -> 2111767 | Q15: Bid Submitted | W15: 0.5 | AA15: GC: EK Bailey | AB15: =IFERROR(VLOOKUP(A15,'Go-No-Go'!$A:$M,12,0),"") | AC15: =IFERROR(VLOOKUP(A15,'Go-No-Go'!$A:$N,14,0),"") | AD15: =IF(OR(Q15="Bid Submitted",Q15="Budget Submitted",Q15="ROM Submitted",Q15="In Progress"),IF(M15<>"",TODAY()-M15,IF(K15<>"",TODAY()-K15,"")),"") -> 105.70833 | AE15: =IF(AND(OR(Q15="Bid Submitted",Q15="Budget Submitted",Q15="ROM Submitted"),X15<>"",X15<TODAY()),"OVERDUE",IF(AND(OR(Q15="Bid Submitted",Q15="Budget Submitted",Q15="ROM Submitted"),X15<>"",X15<=TODAY()+3),"DUE SOON",IF(AND(OR(Q15="Bid Submitted",Q15="Budget Submitted",Q15="ROM Submitted"),X15=""),"MISSING","OK"))) -> MISSING | AF15: =IF(TRIM(IF(B15="","[Missing Project Name] ","")&IF(C15="","[Missing GC] ","")&IF(I15="","[Missing Plumb Estimator] ","")&IF(AND(Q15<>"In Progress",Q15<>"No Bid",Q15<>"On Hold",P15=""),"[Missing Bid Amount] ","")&IF(AND(Q15="Awarded",R15=""),"[Awarded-No Award Amount] ","")&IF(AND(Q15="Lost",U15=""),"[Lost-No Lost Reason] ","")&IF(AND(OR(Q15="Bid Submitted",Q15="Budget Submitted"),X15=""),"[Pending-No Follow-Up Date] ","")&IF(AND(OR(Q15="Bid Submitted",Q15="Budget Submitted"),Y15=""),"[Pending-No Follow-Up Owner] ","")&IF(AND(L15<>"",L15<TODAY(),OR(Q15="In Progress",Q15="")),"[Bid Due Date Passed] ",""))="","OK",TRIM(IF(B15="","[Missing Project Name] ","")&IF(C15="","[Missing GC] ","")&IF(I15="","[Missing Plumb Estimator] ","")&IF(AND(Q15<>"In Progress",Q15<>"No Bid",Q15<>"On Hold",P15=""),"[Missing Bid Amount] ","")&IF(AND(Q15="Awarded",R15=""),"[Awarded-No Award Amount] ","")&IF(AND(Q15="Lost",U15=""),"[Lost-No Lost Reason] ","")&IF(AND(OR(Q15="Bid Submitted",Q15="Budget Submitted"),X15=""),"[Pending-No Follow-Up Date] ","")&IF(AND(OR(Q15="Bid Submitted",Q15="Budget Submitted"),Y15=""),"[Pending-No Follow-Up Owner] ","")&IF(AND(L15<>"",L15<TODAY(),OR(Q15="In Progress",Q15="")),"[Bid Due Date Passed] ",""))) -> [Pending-No Follow-Up Date] [Pending-No Follow-Up Owner]
A16: ASM-2026-015 | B16: Goodyear Flex Bldg | C16: Campbell | D16: Goodyear, AZ | E16: Professional Office | F16: Full Mechanical | G16: Hard Bid | H16: Hard Bid | I16: Patrick | J16: Stephen | K16: 46063.292 | N16: 114514 | O16: 72736 | P16: =IFERROR(IF(AND(N16="",O16=""),"",IFERROR(N16,0)+IFERROR(O16,0)),"") -> 187250 | Q16: Bid Submitted | W16: 0.5 | AA16: GC: Campbell | AB16: =IFERROR(VLOOKUP(A16,'Go-No-Go'!$A:$M,12,0),"") -> 26 | AC16: =IFERROR(VLOOKUP(A16,'Go-No-Go'!$A:$N,14,0),"") -> Review | AD16: =IF(OR(Q16="Bid Submitted",Q16="Budget Submitted",Q16="ROM Submitted",Q16="In Progress"),IF(M16<>"",TODAY()-M16,IF(K16<>"",TODAY()-K16,"")),"") -> 91.708333 | AE16: =IF(AND(OR(Q16="Bid Submitted",Q16="Budget Submitted",Q16="ROM Submitted"),X16<>"",X16<TODAY()),"OVERDUE",IF(AND(OR(Q16="Bid Submitted",Q16="Budget Submitted",Q16="ROM Submitted"),X16<>"",X16<=TODAY()+3),"DUE SOON",IF(AND(OR(Q16="Bid Submitted",Q16="Budget Submitted",Q16="ROM Submitted"),X16=""),"MISSING","OK"))) -> MISSING | AF16: =IF(TRIM(IF(B16="","[Missing Project Name] ","")&IF(C16="","[Missing GC] ","")&IF(I16="","[Missing Plumb Estimator] ","")&IF(AND(Q16<>"In Progress",Q16<>"No Bid",Q16<>"On Hold",P16=""),"[Missing Bid Amount] ","")&IF(AND(Q16="Awarded",R16=""),"[Awarded-No Award Amount] ","")&IF(AND(Q16="Lost",U16=""),"[Lost-No Lost Reason] ","")&IF(AND(OR(Q16="Bid Submitted",Q16="Budget Submitted"),X16=""),"[Pending-No Follow-Up Date] ","")&IF(AND(OR(Q16="Bid Submitted",Q16="Budget Submitted"),Y16=""),"[Pending-No Follow-Up Owner] ","")&IF(AND(L16<>"",L16<TODAY(),OR(Q16="In Progress",Q16="")),"[Bid Due Date Passed] ",""))="","OK",TRIM(IF(B16="","[Missing Project Name] ","")&IF(C16="","[Missing GC] ","")&IF(I16="","[Missing Plumb Estimator] ","")&IF(AND(Q16<>"In Progress",Q16<>"No Bid",Q16<>"On Hold",P16=""),"[Missing Bid Amount] ","")&IF(AND(Q16="Awarded",R16=""),"[Awarded-No Award Amount] ","")&IF(AND(Q16="Lost",U16=""),"[Lost-No Lost Reason] ","")&IF(AND(OR(Q16="Bid Submitted",Q16="Budget Submitted"),X16=""),"[Pending-No Follow-Up Date] ","")&IF(AND(OR(Q16="Bid Submitted",Q16="Budget Submitted"),Y16=""),"[Pending-No Follow-Up Owner] ","")&IF(AND(L16<>"",L16<TODAY(),OR(Q16="In Progress",Q16="")),"[Bid Due Date Passed] ",""))) -> [Pending-No Follow-Up Date] [Pending-No Follow-Up Owner]
A17: ASM-2026-016 | B17: Salt Lake Excavating | C17: Campbell | D17: Salt Lake City, UT | E17: Professional Office | F17: Full Mechanical | G17: Hard Bid | H17: Hard Bid | I17: Patrick | J17: Stephen | K17: 46071.292 | N17: 339849 | O17: 276430 | P17: =IFERROR(IF(AND(N17="",O17=""),"",IFERROR(N17,0)+IFERROR(O17,0)),"") -> 616279 | Q17: Bid Submitted | W17: 0.5 | AA17: GC: Campbell | AB17: =IFERROR(VLOOKUP(A17,'Go-No-Go'!$A:$M,12,0),"") | AC17: =IFERROR(VLOOKUP(A17,'Go-No-Go'!$A:$N,14,0),"") | AD17: =IF(OR(Q17="Bid Submitted",Q17="Budget Submitted",Q17="ROM Submitted",Q17="In Progress"),IF(M17<>"",TODAY()-M17,IF(K17<>"",TODAY()-K17,"")),"") -> 83.708333 | AE17: =IF(AND(OR(Q17="Bid Submitted",Q17="Budget Submitted",Q17="ROM Submitted"),X17<>"",X17<TODAY()),"OVERDUE",IF(AND(OR(Q17="Bid Submitted",Q17="Budget Submitted",Q17="ROM Submitted"),X17<>"",X17<=TODAY()+3),"DUE SOON",IF(AND(OR(Q17="Bid Submitted",Q17="Budget Submitted",Q17="ROM Submitted"),X17=""),"MISSING","OK"))) -> MISSING | AF17: =IF(TRIM(IF(B17="","[Missing Project Name] ","")&IF(C17="","[Missing GC] ","")&IF(I17="","[Missing Plumb Estimator] ","")&IF(AND(Q17<>"In Progress",Q17<>"No Bid",Q17<>"On Hold",P17=""),"[Missing Bid Amount] ","")&IF(AND(Q17="Awarded",R17=""),"[Awarded-No Award Amount] ","")&IF(AND(Q17="Lost",U17=""),"[Lost-No Lost Reason] ","")&IF(AND(OR(Q17="Bid Submitted",Q17="Budget Submitted"),X17=""),"[Pending-No Follow-Up Date] ","")&IF(AND(OR(Q17="Bid Submitted",Q17="Budget Submitted"),Y17=""),"[Pending-No Follow-Up Owner] ","")&IF(AND(L17<>"",L17<TODAY(),OR(Q17="In Progress",Q17="")),"[Bid Due Date Passed] ",""))="","OK",TRIM(IF(B17="","[Missing Project Name] ","")&IF(C17="","[Missing GC] ","")&IF(I17="","[Missing Plumb Estimator] ","")&IF(AND(Q17<>"In Progress",Q17<>"No Bid",Q17<>"On Hold",P17=""),"[Missing Bid Amount] ","")&IF(AND(Q17="Awarded",R17=""),"[Awarded-No Award Amount] ","")&IF(AND(Q17="Lost",U17=""),"[Lost-No Lost Reason] ","")&IF(AND(OR(Q17="Bid Submitted",Q17="Budget Submitted"),X17=""),"[Pending-No Follow-Up Date] ","")&IF(AND(OR(Q17="Bid Submitted",Q17="Budget Submitted"),Y17=""),"[Pending-No Follow-Up Owner] ","")&IF(AND(L17<>"",L17<TODAY(),OR(Q17="In Progress",Q17="")),"[Bid Due Date Passed] ",""))) -> [Pending-No Follow-Up Date] [Pending-No Follow-Up Owner]
A18: ASM-2026-017 | B18: The Hive on 11th | C18: Bonneville | D18: Salt Lake City, UT | E18: Multi-Family | F18: Full Mechanical | G18: Hard Bid | H18: Hard Bid | I18: Patrick | J18: Stephen | K18: 46064.292 | N18: 2809180 | O18: 3496373 | P18: =IFERROR(IF(AND(N18="",O18=""),"",IFERROR(N18,0)+IFERROR(O18,0)),"") -> 6305553 | Q18: Bid Submitted | W18: 0.5 | AA18: GC: Bonneville | AB18: =IFERROR(VLOOKUP(A18,'Go-No-Go'!$A:$M,12,0),"") | AC18: =IFERROR(VLOOKUP(A18,'Go-No-Go'!$A:$N,14,0),"") | AD18: =IF(OR(Q18="Bid Submitted",Q18="Budget Submitted",Q18="ROM Submitted",Q18="In Progress"),IF(M18<>"",TODAY()-M18,IF(K18<>"",TODAY()-K18,"")),"") -> 90.708333 | AE18: =IF(AND(OR(Q18="Bid Submitted",Q18="Budget Submitted",Q18="ROM Submitted"),X18<>"",X18<TODAY()),"OVERDUE",IF(AND(OR(Q18="Bid Submitted",Q18="Budget Submitted",Q18="ROM Submitted"),X18<>"",X18<=TODAY()+3),"DUE SOON",IF(AND(OR(Q18="Bid Submitted",Q18="Budget Submitted",Q18="ROM Submitted"),X18=""),"MISSING","OK"))) -> MISSING | AF18: =IF(TRIM(IF(B18="","[Missing Project Name] ","")&IF(C18="","[Missing GC] ","")&IF(I18="","[Missing Plumb Estimator] ","")&IF(AND(Q18<>"In Progress",Q18<>"No Bid",Q18<>"On Hold",P18=""),"[Missing Bid Amount] ","")&IF(AND(Q18="Awarded",R18=""),"[Awarded-No Award Amount] ","")&IF(AND(Q18="Lost",U18=""),"[Lost-No Lost Reason] ","")&IF(AND(OR(Q18="Bid Submitted",Q18="Budget Submitted"),X18=""),"[Pending-No Follow-Up Date] ","")&IF(AND(OR(Q18="Bid Submitted",Q18="Budget Submitted"),Y18=""),"[Pending-No Follow-Up Owner] ","")&IF(AND(L18<>"",L18<TODAY(),OR(Q18="In Progress",Q18="")),"[Bid Due Date Passed] ",""))="","OK",TRIM(IF(B18="","[Missing Project Name] ","")&IF(C18="","[Missing GC] ","")&IF(I18="","[Missing Plumb Estimator] ","")&IF(AND(Q18<>"In Progress",Q18<>"No Bid",Q18<>"On Hold",P18=""),"[Missing Bid Amount] ","")&IF(AND(Q18="Awarded",R18=""),"[Awarded-No Award Amount] ","")&IF(AND(Q18="Lost",U18=""),"[Lost-No Lost Reason] ","")&IF(AND(OR(Q18="Bid Submitted",Q18="Budget Submitted"),X18=""),"[Pending-No Follow-Up Date] ","")&IF(AND(OR(Q18="Bid Submitted",Q18="Budget Submitted"),Y18=""),"[Pending-No Follow-Up Owner] ","")&IF(AND(L18<>"",L18<TODAY(),OR(Q18="In Progress",Q18="")),"[Bid Due Date Passed] ",""))) -> [Pending-No Follow-Up Date] [Pending-No Follow-Up Owner]
A19: ASM-2026-018 | B19: Radnet Corp. Office | C19: Big-D | E19: Healthcare | F19: Full Mechanical | G19: Hard Bid | H19: Hard Bid | I19: Patrick | J19: Stephen | K19: 46076.292 | N19: 3417972 | O19: 2417425 | P19: =IFERROR(IF(AND(N19="",O19=""),"",IFERROR(N19,0)+IFERROR(O19,0)),"") -> 5835397 | Q19: Bid Submitted | W19: 0.5 | AA19: GCs: Big-D, Westland, Bonneville, R&O, Eckman | AB19: =IFERROR(VLOOKUP(A19,'Go-No-Go'!$A:$M,12,0),"") | AC19: =IFERROR(VLOOKUP(A19,'Go-No-Go'!$A:$N,14,0),"") | AD19: =IF(OR(Q19="Bid Submitted",Q19="Budget Submitted",Q19="ROM Submitted",Q19="In Progress"),IF(M19<>"",TODAY()-M19,IF(K19<>"",TODAY()-K19,"")),"") -> 78.708333 | AE19: =IF(AND(OR(Q19="Bid Submitted",Q19="Budget Submitted",Q19="ROM Submitted"),X19<>"",X19<TODAY()),"OVERDUE",IF(AND(OR(Q19="Bid Submitted",Q19="Budget Submitted",Q19="ROM Submitted"),X19<>"",X19<=TODAY()+3),"DUE SOON",IF(AND(OR(Q19="Bid Submitted",Q19="Budget Submitted",Q19="ROM Submitted"),X19=""),"MISSING","OK"))) -> MISSING | AF19: =IF(TRIM(IF(B19="","[Missing Project Name] ","")&IF(C19="","[Missing GC] ","")&IF(I19="","[Missing Plumb Estimator] ","")&IF(AND(Q19<>"In Progress",Q19<>"No Bid",Q19<>"On Hold",P19=""),"[Missing Bid Amount] ","")&IF(AND(Q19="Awarded",R19=""),"[Awarded-No Award Amount] ","")&IF(AND(Q19="Lost",U19=""),"[Lost-No Lost Reason] ","")&IF(AND(OR(Q19="Bid Submitted",Q19="Budget Submitted"),X19=""),"[Pending-No Follow-Up Date] ","")&IF(AND(OR(Q19="Bid Submitted",Q19="Budget Submitted"),Y19=""),"[Pending-No Follow-Up Owner] ","")&IF(AND(L19<>"",L19<TODAY(),OR(Q19="In Progress",Q19="")),"[Bid Due Date Passed] ",""))="","OK",TRIM(IF(B19="","[Missing Project Name] ","")&IF(C19="","[Missing GC] ","")&IF(I19="","[Missing Plumb Estimator] ","")&IF(AND(Q19<>"In Progress",Q19<>"No Bid",Q19<>"On Hold",P19=""),"[Missing Bid Amount] ","")&IF(AND(Q19="Awarded",R19=""),"[Awarded-No Award Amount] ","")&IF(AND(Q19="Lost",U19=""),"[Lost-No Lost Reason] ","")&IF(AND(OR(Q19="Bid Submitted",Q19="Budget Submitted"),X19=""),"[Pending-No Follow-Up Date] ","")&IF(AND(OR(Q19="Bid Submitted",Q19="Budget Submitted"),Y19=""),"[Pending-No Follow-Up Owner] ","")&IF(AND(L19<>"",L19<TODAY(),OR(Q19="In Progress",Q19="")),"[Bid Due Date Passed] ",""))) -> [Pending-No Follow-Up Date] [Pending-No Follow-Up Owner]
A20: ASM-2026-019 | B20: Kari Sue Hamilton Remodel | C20: Judd | E20: Education | F20: Full Mechanical | G20: Hard Bid | H20: Hard Bid | I20: Patrick | J20: Stephen | K20: 46057.292 | N20: 131701 | O20: 153676 | P20: =IFERROR(IF(AND(N20="",O20=""),"",IFERROR(N20,0)+IFERROR(O20,0)),"") -> 285377 | Q20: Bid Submitted | W20: 0.5 | AA20: GCs: Judd, Mahas | AB20: =IFERROR(VLOOKUP(A20,'Go-No-Go'!$A:$M,12,0),"") | AC20: =IFERROR(VLOOKUP(A20,'Go-No-Go'!$A:$N,14,0),"") | AD20: =IF(OR(Q20="Bid Submitted",Q20="Budget Submitted",Q20="ROM Submitted",Q20="In Progress"),IF(M20<>"",TODAY()-M20,IF(K20<>"",TODAY()-K20,"")),"") -> 97.708333 | AE20: =IF(AND(OR(Q20="Bid Submitted",Q20="Budget Submitted",Q20="ROM Submitted"),X20<>"",X20<TODAY()),"OVERDUE",IF(AND(OR(Q20="Bid Submitted",Q20="Budget Submitted",Q20="ROM Submitted"),X20<>"",X20<=TODAY()+3),"DUE SOON",IF(AND(OR(Q20="Bid Submitted",Q20="Budget Submitted",Q20="ROM Submitted"),X20=""),"MISSING","OK"))) -> MISSING | AF20: =IF(TRIM(IF(B20="","[Missing Project Name] ","")&IF(C20="","[Missing GC] ","")&IF(I20="","[Missing Plumb Estimator] ","")&IF(AND(Q20<>"In Progress",Q20<>"No Bid",Q20<>"On Hold",P20=""),"[Missing Bid Amount] ","")&IF(AND(Q20="Awarded",R20=""),"[Awarded-No Award Amount] ","")&IF(AND(Q20="Lost",U20=""),"[Lost-No Lost Reason] ","")&IF(AND(OR(Q20="Bid Submitted",Q20="Budget Submitted"),X20=""),"[Pending-No Follow-Up Date] ","")&IF(AND(OR(Q20="Bid Submitted",Q20="Budget Submitted"),Y20=""),"[Pending-No Follow-Up Owner] ","")&IF(AND(L20<>"",L20<TODAY(),OR(Q20="In Progress",Q20="")),"[Bid Due Date Passed] ",""))="","OK",TRIM(IF(B20="","[Missing Project Name] ","")&IF(C20="","[Missing GC] ","")&IF(I20="","[Missing Plumb Estimator] ","")&IF(AND(Q20<>"In Progress",Q20<>"No Bid",Q20<>"On Hold",P20=""),"[Missing Bid Amount] ","")&IF(AND(Q20="Awarded",R20=""),"[Awarded-No Award Amount] ","")&IF(AND(Q20="Lost",U20=""),"[Lost-No Lost Reason] ","")&IF(AND(OR(Q20="Bid Submitted",Q20="Budget Submitted"),X20=""),"[Pending-No Follow-Up Date] ","")&IF(AND(OR(Q20="Bid Submitted",Q20="Budget Submitted"),Y20=""),"[Pending-No Follow-Up Owner] ","")&IF(AND(L20<>"",L20<TODAY(),OR(Q20="In Progress",Q20="")),"[Bid Due Date Passed] ",""))) -> [Pending-No Follow-Up Date] [Pending-No Follow-Up Owner]
